<?xml version="1.0"?>
<robot xmlns:xacro="http://www.ros.org/wiki/xacro">
   <xacro:include filename="$(find robot_description)/urdf/common_inertia.xacro" />
    <xacro:macro name="rotating_base_xacro" params="rotating_base_name xyz">
        <link name="${rotating_base_name}_link">
            <visual>
                <origin xyz="0 0 0" rpy="0 0 0" />
                <geometry>
                    <cylinder length="0.02" radius="0.04" />
                </geometry>
                <material name="black">
                    <color rgba="0.0 0.0 0.0 0.8"/>
                </material>
            </visual>
            <collision>
                <origin xyz="0 0 0" rpy="0 0 0" />
                <geometry>
                    <cylinder length="0.02" radius="0.04" />
                </geometry>
                <material name="black">
                    <color rgba="0.0 0.0 0.0 0.8"/>
                </material>
            </collision>
            <xacro:cylinder_inertia m="0.1" h="0.02" r="0.04"/>
        </link>
        <gazebo reference="${rotating_base_name}_link">
            <material>Gazebo/Black</material>
        </gazebo>

        <joint name="${rotating_base_name}_joint" type="continuous">
            <parent link="base_link" />
            <child link="${rotating_base_name}_link" />
            <origin xyz="${xyz}" />
            <axis xyz="0 0 1" />
        </joint>
    </xacro:macro>
</robot>
